Workbook

Sheet Dashboard
A1: DOMME × LASZLO
A2: Motor de Precificação v3 — Perfeição Operacional
A4: 📊 KPIs DO ECOSSISTEMA
A5: Total SKUs no Catálogo | B5: 589
A6: SKUs Disponíveis para White Label | B6: 491
A7: SKUs em Risco de Estoque | B7: 98
A8: SKUs em Retirada de Linha | B8: 0
A9: Matérias-Primas Cadastradas | B9: 2583
A10: Ticket Médio Geral Laszlo (R$) | B10: 58
A11: Fee DOMME por Projeto (R$) | B11: 1500
A13: 🗂️ NAVEGAÇÃO DAS ABAS
A14: ➤ Motor v3 | B14: Simulador principal — insira SKU, lote e preço
A15: ➤ Cenários | B15: Comparativo de escala (Tier 1 vs Tier 2 vs Tier 3)
A16: ➤ Exportação | B16: Módulo internacional — USD/EUR com markup 8x
A17: ➤ Proposta | B17: Layout PDF-ready para envio ao cliente
A18: ➤ Catálogo Laszlo | B18: 589 SKUs com status WL e benchmarks
A19: ➤ Base cadastro MP | B19: 2583 matérias-primas com custo real
A20: ➤ Check_Retirada | B20: 48 produtos em descontinuação
A21: ➤ Parâmetros v3 | B21: Margens, tiers, fees e regras editáveis
A22: ➤ Regras v3 | B22: Documentação completa das regras de negócio
A24: ⚠️ NOTAS IMPORTANTES
A25: 1. Desconto de 15% no ROI é conservador. Em marketplaces (ML, Shopee), taxas chegam a 18-22%.
A26: 2. Templates técnicos: verso (dados legais) é IMUTÁVEL. Design exclusivo é serviço à parte.
A27: 3. Foco regulatório: Aromas Naturais / Alimentos para rapidez de mercado.
A28: 4. Células AZUIS são editáveis. Células PRETAS são fórmulas — não altere.

Sheet Motor v3
A1: DOMME × LASZLO — SIMULADOR v3
A2: Precificação por Lote · Full-Service · Métricas de Sucesso
A4: ▸ ENTRADA DO CLIENTE
A6: SKU (selecione do catálogo) | B6: ABS ALGAS-MARINHAS 10 GT FRANCA 10ML | C6: Menu suspenso ↓
A7: Volume por Lote (unidades) | B7: 200 | C7: Qtd produzida de uma só vez
A8: Preço de Venda ao Consumidor (R$) | C8: Se vazio, usa Varejo Laszlo
A9: Mercado | B9: Brasil | C9: Brasil / Internacional
A11: ▸ DADOS DO PRODUTO (automático via catálogo)
A13: Código Laszlo | B13: =IFERROR(VLOOKUP(B6,'Catálogo Laszlo'!A:I,2,FALSE()),"—") -> 1124 | C13: PROCV automático
A14: CVU Matéria-Prima (R$) | B14: =IFERROR(VLOOKUP(B6,'Catálogo Laszlo'!A:I,3,FALSE()),0) -> 46.145535 | C14: Custo unitário real da fábrica
A15: Ticket Médio Vendas Laszlo (R$) | B15: =IFERROR(VLOOKUP(B6,'Catálogo Laszlo'!A:I,4,FALSE()),0) -> 167.47941 | C15: Benchmark de mercado
A16: Volume do Frasco (ml) | B16: =IFERROR(VLOOKUP(B6,'Catálogo Laszlo'!A:I,9,FALSE()),10) -> 10 | C16: Extraído do nome
A17: Status WL do Produto | B17: =IFERROR(VLOOKUP(B6,'Catálogo Laszlo'!A:I,8,FALSE()),"—") -> ✓ Disponível | C17: Verifica disponibilidade
A19: ▸ INTELIGÊNCIA DE CUSTOS (Full-Service)
A21: Kit de Envase Base (frasco+tampa+got.) R$ | B21: 2.5 | C21: Custo base unitário do kit
A22: Fator de Escala Insumos | B22: =IF(B7<=100,2,1) -> 1 | C22: Lote ≤100: 2x | >100: 1x
A23: Custo Envase Ajustado (R$) | B23: =B21*B22 -> 2.5 | C23: Kit × Fator de Escala
A24: CVU Total (MP + Envase) | B24: =B14+B23 -> 48.645535
A25: Fee DOMME Rateado (R$1.500 ÷ Lote) | B25: =IF(B7>0,1500/B7,0) -> 7.5
A26: Custo Total Unitário c/ Fee (R$) | B26: =B24+B25 -> 56.145535
A28: ▸ DECOMPOSIÇÃO DE PREÇO
A30: MIL — Margem Industrial Laszlo | B30: 0.4 | C30: Mínimo 20% MC garantido
A31: PI Laszlo (= CVU Total × (1+MIL)) | B31: =B24*(1+B30) -> 68.103749
A32: MD — Margem Comercial DOMME | B32: 0.2
A33: Selo Laszlo | B33: 0.03
A34: Markup de Volume (auto por lote) | B34: =IF(B7<=500,0.2,IF(B7<=2000,0.1,0)) -> 0.2 | C34: T1≤500:20% | T2≤2000:10% | T3>2000:0%
A35: Tier Identificado | B35: =IF(B7<=500,"Tier 1 — Boutique",IF(B7<=2000,"Tier 2 — Growth","Tier 3 — Scale")) -> Tier 1 — Boutique
A36: PFC Unitário Brasil (R$) | B36: =B31*(1+B32)*(1+B34)*(1+B33) -> 101.01148 | C36: Preço Final ao Cliente DOMME
A37: PFC Export (se Internacional) | B37: =IF(B9="Internacional",B24*8,B36) -> 101.01148 | C37: Markup 8x para OEs no exterior
A38: PFC FINAL (R$) | B38: =IF(B9="Internacional",B37,B36) -> 101.01148 | C38: Auto: Brasil ou Export
A40: ▸ MÉTRICAS DE SUCESSO DO CLIENTE
A42: Preço de Venda Efetivo (R$) | B42: =IF(B8="",B15,B8) -> 167.47941 | C42: Usa input ou Ticket Médio Laszlo
A43: Índice de Viabilidade (IV) | B43: =IF(B15>0,B38/B15,"—") -> 0.60312775 | C43: PFC ÷ Varejo Laszlo (ideal < 0.55)
A44: Status IV | B44: =IF(B43="—","Sem dados",IF(B43<0.55,"✓ VIÁVEL — Proposta Saudável",IF(B43<=0.7,"⚠ ATENÇÃO — Margem Apertada","✗ CRÍTICO — Rever Custos"))) -> ⚠ ATENÇÃO — Margem Apertada
A45: Alerta Competitividade | B45: =IF(B42>B15*1.2,"⚠ Preço acima de 120% do benchmark","✓ Competitivo") -> ✓ Competitivo
A46: Investimento Inicial Total (R$) | B46: =B38*B7+1500 -> 21702.296 | C46: (PFC × Lote) + Fee
A47: Preço Venda Líquido (−15% imp/frete) | B47: =B42*0.85 -> 142.3575
A48: Margem Líquida por Unidade (R$) | B48: =B47-B38 -> 41.34602
A49: Break-Even Real (unidades) | B49: =IF(B48>0,ROUNDUP(B46/B48,0),"Inviável") -> 525 | C49: Unidades para cobrir investimento
A50: Lucro Líquido Projetado no Lote (R$) | B50: =IF(B48>0,B48*B7,0) -> 8269.2039
...

Sheet Cenários
A1: ANÁLISE DE GANHO EM ESCALA — Simulador de Cenários
A2: "E se eu produzir mais?" — Comparativo automático de 3 cenários de lote
A3: Produto selecionado: | B3: ='Motor v3'!B6 -> ABS ALGAS-MARINHAS 10 GT FRANCA 10ML
A5: Métrica | B5: Cenário 1: 50 un | C5: Cenário 2: 200 un | D5: Cenário 3: 500 un | E5: Cenário 4: 1.000 un
A6: Tier | B6: ="Tier 1" -> Tier 1 | C6: ="Tier 1" -> Tier 1 | D6: ="Tier 1" -> Tier 1 | E6: ="Tier 2" -> Tier 2
A7: Markup Volume | B7: =0.2 -> 0.2 | C7: =0.2 -> 0.2 | D7: =0.2 -> 0.2 | E7: =0.1 -> 0.1
A8: Fator Escala Envase | B8: =2 -> 2 | C8: =1 -> 1 | D8: =1 -> 1 | E8: =1 -> 1
A9: Custo Envase Ajustado | B9: ='Motor v3'!B21*2 -> 5 | C9: ='Motor v3'!B21*1 -> 2.5 | D9: ='Motor v3'!B21*1 -> 2.5 | E9: ='Motor v3'!B21*1 -> 2.5
A10: CVU Total (MP+Envase) | B10: ='Motor v3'!B14+'Motor v3'!B21*2 -> 51.145535 | C10: ='Motor v3'!B14+'Motor v3'!B21 -> 48.645535 | D10: ='Motor v3'!B14+'Motor v3'!B21 -> 48.645535 | E10: ='Motor v3'!B14+'Motor v3'!B21 -> 48.645535
A11: Fee Rateado (R$) | B11: =1500/50 -> 30 | C11: =1500/200 -> 7.5 | D11: =1500/500 -> 3 | E11: =1500/1000 -> 1.5
A12: Custo Unit. c/ Fee (R$) | B12: =('Motor v3'!B14+'Motor v3'!B21*2)+1500/50 -> 81.145535 | C12: =('Motor v3'!B14+'Motor v3'!B21)+1500/200 -> 56.145535 | D12: =('Motor v3'!B14+'Motor v3'!B21)+1500/500 -> 51.645535 | E12: =('Motor v3'!B14+'Motor v3'!B21)+1500/1000 -> 50.145535
A13: PI Laszlo (R$) | B13: =('Motor v3'!B14+'Motor v3'!B21*2)*(1+'Motor v3'!B30) -> 71.603749 | C13: =('Motor v3'!B14+'Motor v3'!B21)*(1+'Motor v3'!B30) -> 68.103749 | D13: =('Motor v3'!B14+'Motor v3'!B21)*(1+'Motor v3'!B30) -> 68.103749 | E13: =('Motor v3'!B14+'Motor v3'!B21)*(1+'Motor v3'!B30) -> 68.103749
A14: PFC Unitário (R$) | B14: =('Motor v3'!B14+'Motor v3'!B21*2)*(1+'Motor v3'!B30)*(1+'Motor v3'!B32)*(1+0.2)*(1+'Motor v3'!B33) -> 106.20268 | C14: =('Motor v3'!B14+'Motor v3'!B21)*(1+'Motor v3'!B30)*(1+'Motor v3'!B32)*(1+0.2)*(1+'Motor v3'!B33) -> 101.01148 | D14: =('Motor v3'!B14+'Motor v3'!B21)*(1+'Motor v3'!B30)*(1+'Motor v3'!B32)*(1+0.2)*(1+'Motor v3'!B33) -> 101.01148 | E14: =('Motor v3'!B14+'Motor v3'!B21)*(1+'Motor v3'!B30)*(1+'Motor v3'!B32)*(1+0.1)*(1+'Motor v3'!B33) -> 92.593857
A15: Investimento Total (R$) | B15: =(('Motor v3'!B14+'Motor v3'!B21*2)*(1+'Motor v3'!B30)*(1+'Motor v3'!B32)*(1+0.2)*(1+'Motor v3'!B33))*50+1500 -> 6810.134 | C15: =(('Motor v3'!B14+'Motor v3'!B21)*(1+'Motor v3'!B30)*(1+'Motor v3'!B32)*(1+0.2)*(1+'Motor v3'!B33))*200+1500 -> 21702.296 | D15: =(('Motor v3'!B14+'Motor v3'!B21)*(1+'Motor v3'!B30)*(1+'Motor v3'!B32)*(1+0.2)*(1+'Motor v3'!B33))*500+1500 -> 52005.74 | E15: =(('Motor v3'!B14+'Motor v3'!B21)*(1+'Motor v3'!B30)*(1+'Motor v3'!B32)*(1+0.1)*(1+'Motor v3'!B33))*1000+1500 -> 94093.857
A16: Margem Líquida Unit. (R$) | B16: ='Motor v3'!B42*0.85-('Motor v3'!B14+'Motor v3'!B21*2)*(1+'Motor v3'!B30)*(1+'Motor v3'!B32)*(1+0.2)*(1+'Motor v3'!B33) -> 36.15482 | C16: ='Motor v3'!B42*0.85-('Motor v3'!B14+'Motor v3'!B21)*(1+'Motor v3'!B30)*(1+'Motor v3'!B32)*(1+0.2)*(1+'Motor v3'!B33) -> 41.34602 | D16: ='Motor v3'!B42*0.85-('Motor v3'!B14+'Motor v3'!B21)*(1+'Motor v3'!B30)*(1+'Motor v3'!B32)*(1+0.2)*(1+'Motor v3'!B33) -> 41.34602 | E16: ='Motor v3'!B42*0.85-('Motor v3'!B14+'Motor v3'!B21)*(1+'Motor v3'!B30)*(1+'Motor v3'!B32)*(1+0.1)*(1+'Motor v3'!B33) -> 49.763643
A17: Lucro Líquido Lote (R$) | B17: =('Motor v3'!B42*0.85-('Motor v3'!B14+'Motor v3'!B21*2)*(1+'Motor v3'!B30)*(1+'Motor v3'!B32)*(1+0.2)*(1+'Motor v3'!B33))*50 -> 1807.741 | C17: =('Motor v3'!B42*0.85-('Motor v3'!B14+'Motor v3'!B21)*(1+'Motor v3'!B30)*(1+'Motor v3'!B32)*(1+0.2)*(1+'Motor v3'!B33))*200 -> 8269.2039 | D17: =('Motor v3'!B42*0.85-('Motor v3'!B14+'Motor v3'!B21)*(1+'Motor v3'!B30)*(1+'Motor v3'!B32)*(1+0.2)*(1+'Motor v3'!B33))*500 -> 20673.01 | E17: =('Motor v3'!B42*0.85-('Motor v3'!B14+'Motor v3'!B21)*(1+'Motor v3'!B30)*(1+'Motor v3'!B32)*(1+0.1)*(1+'Motor v3'!B33))*1000 -> 49763.643
A19: 💡 INSIGHT: Ao aumentar o lote, o Fee rateado cai drasticamente e o lucro por unidade sobe.

Sheet Exportação
A1: MÓDULO DE EXPORTAÇÃO — WL Export
A3: ▸ COTAÇÕES (editável)
A5: Cotação USD → BRL | B5: 5.5 | C5: Edite conforme câmbio do dia
A6: Cotação EUR → BRL | B6: 5.9 | C6: Edite conforme câmbio do dia
A7: Frete Internacional Estimado (USD/un) | B7: 2 | C7: Custo estimado por unidade
A9: ▸ PRECIFICAÇÃO INTERNACIONAL
A11: Produto | B11: ='Motor v3'!B6 -> ABS ALGAS-MARINHAS 10 GT FRANCA 10ML
A12: CVU Total (R$) | B12: ='Motor v3'!B24 -> 48.645535
A13: PFC Export (Markup 8x, R$) | B13: ='Motor v3'!B24*8 -> 389.16428 | C13: Sem impostos internos (IPI/ICMS removidos)
A14: PFC Export (USD) | B14: =B13/B5 -> 70.757142
A15: PFC Export (EUR) | B15: =B13/B6 -> 65.960047
A16: PFC + Frete (USD) | B16: =B14+B7 -> 72.757142
A17: PFC + Frete (EUR) | B17: =B15+(B7*B5/B6) -> 67.824454
A19: ▸ NOTA: IPI e ICMS removidos. Produto segue como Aroma Natural/Alimento.

Sheet Proposta
A1: PROPOSTA COMERCIAL — WHITE LABEL
A2: DOMME × Laszlo Aromaterapia
A3: ────────────────────────────────────────────────────────────
A5: PRODUTO SELECIONADO
A7: Produto | B7: ='Motor v3'!B6 -> ABS ALGAS-MARINHAS 10 GT FRANCA 10ML
A8: Tier de Operação | B8: ='Motor v3'!B35 -> Tier 1 — Boutique
A9: Volume do Lote | B9: ='Motor v3'!B7 -> 200
A10: Mercado | B10: ='Motor v3'!B9 -> Brasil
A12: INVESTIMENTO DO CLIENTE
A14: Preço Unitário (PFC) | B14: ='Motor v3'!B38 -> 101.01148
A15: Fee de Estruturação DOMME | B15: =1500 -> 1500 | C15: One-time
A16: Investimento Total | B16: ='Motor v3'!B46 -> 21702.296
A18: RETORNO PROJETADO (Conservador)
A20: Preço de Venda Sugerido | B20: ='Motor v3'!B42 -> 167.47941
A21: Margem Líquida por Unidade | B21: ='Motor v3'!B48 -> 41.34602 | C21: Já descontado 15% (impostos+frete)
A22: Break-Even | B22: ='Motor v3'!B49 -> 525 | C22: Unidades para cobrir investimento
A23: Lucro Líquido no Lote | B23: ='Motor v3'!B50 -> 8269.2039
A24: ROI Conservador | B24: ='Motor v3'!B51 -> 0.38102899
A26: STATUS DE VIABILIDADE
A28: Índice de Viabilidade (IV) | B28: ='Motor v3'!B43 -> 0.60312775 | C28: Ideal < 0.55
A29: Diagnóstico | B29: ='Motor v3'!B44 -> ⚠ ATENÇÃO — Margem Apertada
A30: Competitividade | B30: ='Motor v3'!B45 -> ✓ Competitivo
A32: ────────────────────────────────────────────────────────────
A33: O que está incluído: Produto Laszlo padrão + Rótulo do cliente + Selo Laszlo
A34: Template técnico (verso): dados legais imutáveis. Design exclusivo: serviço à parte.
A35: Foco regulatório: Aromas Naturais / Alimentos para rapidez de mercado.
A37: DOMME — Inteligência em White Label

Sheet Catálogo Laszlo
A1: Nome do Produto | B1: Código | C1: CVU (R$) | D1: Ticket Médio (R$) | E1: Vendas 2024 | F1: Ranking | G1: % MC Real | H1: Status WL | I1: Volume (ml)
A2: ABS ALGAS-MARINHAS 10 GT FRANCA 10ML | B2: 1124 | C2: 46.145535 | D2: 167.47941 | E2: 34 | F2: 241 | G2: 0.2744704 | H2: ✓ Disponível | I2: 10
A3: ABS BAUNILHA 10 GT MADAGASCAR 10ML | B3: 707 | C3: 40.70176 | D3: 128.02336 | E3: 238 | F3: 71 | G3: 0.23207552 | H3: ✓ Disponível | I3: 10
A4: ABS BENJOIM-DO-SIAO GT LAOS 10ML | B4: 708 | C4: 9.36456 | D4: 43.6443 | E4: 486 | F4: 69 | G4: 0.33543453 | H4: ✓ Disponível | I4: 10
A5: ABS CACAU CHOCOLATE 30 GT FRANCA 10ML | B5: 968 | C5: 27.849811 | D5: 167.4 | E5: 10 | F5: 205 | G5: 0.38363315 | H5: ✓ Disponível | I5: 10
A6: ABS CACAU GT EUA 5ML | B6: 2184 | C6: 8.95709 | D6: 0 | E6: 0 | F6: NOVO | G6: 0 | H6: ⚠ Risco Estoque | I6: 5
A7: ABS JASMIM-SAMBAC 10 GT INDIA 10ML | B7: 1131 | C7: 32.42397 | D7: 174.3 | E7: 72 | F7: 121 | G7: 0.36397608 | H7: ✓ Disponível | I7: 10
A8: ABS LADANO CISTO GT ESPANHA 5ML | B8: 1119 | C8: 14.193 | D8: 75.712671 | E8: 161 | F8: 116 | G8: 0.36254128 | H8: ✓ Disponível | I8: 5
A9: ABS LAVANDIM GROSSO GT FRANCA 10ML | B9: 972 | C9: 15.26959 | D9: 0 | E9: 0 | F9: 456 | G9: 0 | H9: ⚠ Risco Estoque | I9: 10
A10: ABS MUSGO-DE-CARVALHO GT MACEDONIA 10ML | B10: 1374 | C10: 16.4426 | D10: 107.60769 | E10: 13 | F10: 207 | G10: 0.39719866 | H10: ✓ Disponível | I10: 10
A11: ABS SEMPRE-VIVA-DAS-AREIAS 10 GT ESPANHA 10ML | B11: 1120 | C11: 14.22293 | D11: 59.266667 | E11: 3 | F11: 436 | G11: 0.31001805 | H11: ⚠ Risco Estoque | I11: 10
A12: BL AMBAR-FOSSIL 5ML | B12: 1104 | C12: 13.93959 | D12: 40 | E12: 1 | F12: 451 | G12: 0.20151025 | H12: ⚠ Risco Estoque | I12: 5
A13: BL GLICINIA 5ML | B13: 1079 | C13: 35.873982 | D13: 110.55254 | E13: 59 | F13: 315 | G13: 0.22550287 | H13: ✓ Disponível | I13: 5
A14: BL INCENSO 5ML | B14: 873 | C14: 20.049907 | D14: 77.020408 | E14: 98 | F14: 308 | G14: 0.28968059 | H14: ✓ Disponível | I14: 5
A15: BL LIRIO-DO-VALE 5ML | B15: 1105 | C15: 28.792117 | D15: 85.352402 | E15: 204 | F15: 135 | G15: 0.21266775 | H15: ✓ Disponível | I15: 5
A16: BL MADRESSILVA 5ML | B16: 1090 | C16: 21.59389 | D16: 88.433333 | E16: 72 | F16: 311 | G16: 0.3058173 | H16: ✓ Disponível | I16: 5
A17: BL MELISSA 5ML | B17: 839 | C17: 8.82959 | D17: 27.60119 | E17: 336 | F17: 165 | G17: 0.23010112 | H17: ✓ Disponível | I17: 5
A18: BL MUSK 5ML | B18: 1375 | C18: 16.40659 | D18: 85 | E18: 1 | F18: 442 | G18: 0.35698129 | H18: ⚠ Risco Estoque | I18: 5
... A187: EXC OE SALSA FOLHAS GT BRASIL 10ML (GOURMET) | B187: 1976 | C187: 12.83139 | D187: 53.95 | E187: 10 | F187: 399 | G187: 0.31216145 | H187: ✓ Disponível | I187: 10
A188: EXC OE SALSA FOLHAS GT EUA 5ML | B188: 2190 | C188: 7.09959 | D188: 0 | E188: 0 | F188: NOVO | G188: 0 | H188: ⚠ Risco Estoque | I188: 5
A189: EXC OE SALVIA TRILOBA CO2-TO GT TURQUIA 5ML | B189: 2109 | C189: 7.48259 | D189: 30.47037 | E189: 27 | F189: 388 | G189: 0.30443062 | H189: ✓ Disponível | I189: 5
A190: EXC OE SALVIA-BRANCA GT EUA 5ML | B190: 973 | C190: 1.26959 | D190: 106.4 | E190: 2 | F190: 413 | G190: 0.53806776 | H190: ⚠ Risco Estoque | I190: 5
A191: EXC OE SALVIA-ESCLAREIA GT EUA 5ML | B191: 1161 | C191: 15.529044 | D191: 74.028974 | E191: 78 | F191: 236 | G191: 0.34023019 | H191: ✓ Disponível | I191: 5
A192: EXC OE SEGURELHA GT ITALIA 5ML | B192: 2080 | C192: 8.14479 | D192: 27 | E192: 1 | F192: 454 | G192: 0.24834111 | H192: ⚠ Risco Estoque | I192: 5
A193: EXC OE SEMPRE-VIVA IMMORTELLE GT BOSNIA 5ML | B193: 773 | C193: 28.793859 | D193: 158.57311 | E193: 61 | F193: 130 | G193: 0.36841903 | H193: ✓ Disponível | I193: 5
A194: EXC OE SEMPRE-VIVA-DAS-AREIAS 10 GT PORTUGAL | B194: 2177 | C194: 8.53836 | D194: 0 | E194: 0 | F194: 473 | G194: 0 | H194: ⚠ Risco Estoque | I194: 10
A195: EXC OE SHISO GT JAPAO 5ML | B195: 978 | C195: 58.34459 | D195: 207.27417 | E195: 12 | F195: 348 | G195: 0.2685149 | H195: ✓ Disponível | I195: 5
A196: EXC OE TAGETES GT MADAGASCAR 10ML | B196: 919 | C196: 31.85559 | D196: 0 | E196: 0 | F196: 490 | G196: 0 | H196: ⚠ Risco Estoque | I196: 10
A197: EXC OE TANA GT MADAGASCAR 10ML | B197: 2098 | C197: 6.17959 | D197: 35.026667 | E197: 9 | F197: 412 | G197: 0.37357471 | H197: ⚠ Risco Estoque | I197: 10
A198: EXC OE TANACETO-AZUL GT MARROCOS 5ML | B198: 902 | C198: 44.55959 | D198: 155.98074 | E198: 27 | F198: 196 | G198: 0.26432633 | H198: ✓ Disponível | I198: 5
A199: EXC OE TEA TREE LIMAO GT AUSTRALIA 5ML | B199: 2159 | C199: 12.09749 | D199: 39.966667 | E199: 15 | F199: 404 | G199: 0.24731051 | H199: ✓ Disponível | I199: 5
A200: EXC OE TOMILHO QT BORNEOL GT MARROCOS 10ML | B200: 967 | C200: 27.27729 | D200: 107.29889 | E200: 9 | F200: 383 | G200: 0.29578218 | H200: ✓ Disponível | I200: 10
... A305: OE ALECRIM QT CANFORA GT ESPANHA 50ML | B305: 943 | C305: 19.81709 | D305: 126.12719 | E305: 167 | F305: 62 | G305: 0.39288011 | H305: ✓ Disponível | I305: 50
A306: OE ALECRIM QT MIRCENO GT BRASIL 5ML | B306: 2198 | C306: 6.84074 | D306: 0 | E306: 0 | F306: NOVO | G306: 0 | H306: ⚠ Risco Estoque | I306: 5
A307: OE ALECRIM QT VERBENONA GT MALAWI 5ML | B307: 1144 | C307: 8.84119 | D307: 41.350303 | E307: 99 | F307: 243 | G307: 0.33618802 | H307: ✓ Disponível | I307: 5
A308: OE ALECRIM-DO-CAMPO GT BRASIL 5ML | B308: 1149 | C308: 10.42959 | D308: 46.878519 | E308: 135 | F308: 174 | G308: 0.32751878 | H308: ✓ Disponível | I308: 5
A309: OE ALECRIM-PIMENTA GT BRASIL 10ML | B309: 1373 | C309: 7.98629 | D309: 41.6 | E309: 6 | F309: 420 | G309: 0.35802187 | H309: ⚠ Risco Estoque | I309: 10
A310: OE ALECRIM-SELVAGEM GT AFRICA-DO-SUL 5ML | B310: 1152 | C310: 25.410243 | D310: 84.2776 | E310: 25 | F310: 354 | G310: 0.24849352 | H310: ✓ Disponível | I310: 5
A311: OE AMAZONGRASS GT BRASIL 5ML | B311: 2197 | C311: 2.87644 | D311: 0 | E311: 0 | F311: NOVO | G311: 0 | H311: ⚠ Risco Estoque | I311: 5
A312: OE AMENDOAS AMARGAS GT EUA 10ML | B312: 938 | C312: 12.23269 | D312: 39.6 | E312: 3 | F312: 288 | G312: 0.24109369 | H312: ✓ Disponível | I312: 10
...

Sheet Base cadastro MP
A1: Código MP | B1: Nome MP | C1: Und | D1: Fabricante | E1: Classificação | F1: Qtd Min | G1: Preço Custo Real
A2: 1334 | B2: ABS ACACIA DOCE | C2: KG | D2: LIBERTY NATURAL | E2: ABSOLUTOS. | F2: 0 | G2: 17584
A3: 716 | B3: ABS ACACIA MIMOSA ABSOLUTO GT FRANÇA | C3: KG | D3: THE PERFUMERY | E3: ABSOLUTOS. | F3: 0.113 | G3: 4280.09
A4: 1333 | B4: ABS AÇAFRAO GT FRANÇA | C4: KG | D4: LIBERTY NATURAL | E4: ABSOLUTOS. | F4: 0 | G4: 11298
A5: 1463 | B5: ABS AÇAFROA (CÁRTAMO) GT INDIA | C5: ML | D5: LIBERTY NATURAL | E5: ABSOLUTOS. | F5: 0 | G5: 6.58
A6: 1459 | B6: ABS ALGAS MARINHAS | C6: KG | D6: NORFOLK | E6: OLEO ESSENCIAL | F6: 0 | G6: 37469.65
A7: 557 | B7: ABS AMBAR ESTORAQUE | C7: KG | D7: INTERLINK | E7: ABSOLUTOS. | F7: 0 | G7: 1042.22
A8: 1465 | B8: ABS ANGELICA RAIZES | C8: KG | D8: IMPORTADO | E8: ABSOLUTOS. | F8: 0 | G8: 12155
A9: 1466 | B9: ABS ARNICA MONTANA GT FRANÇA | C9: KG | D9: LIBERTY NATURAL | E9: ABSOLUTOS. | F9: 0 | G9: 14097
A10: 2656 | B10: ABS AZEVEM SECO GT FRANÇA | C10: KG | D10: LIBERTY NATURAL | E10: ABSOLUTOS. | F10: 0 | G10: 12955
A11: 1331 | B11: ABS BALSAMO DO PERU ABSOLUTO | C11: KG | D11: INTERLINK | E11: ABSOLUTOS. | F11: 1 | G11: 714.76
A12: 1467 | B12: ABS BALSAMO DO TOLU ABSOLUTO | C12: KG | D12: LIBERTY NATURAL | E12: ABSOLUTOS. | F12: 0 | G12: 991.08
A13: 1468 | B13: ABS BAUNILHA | C13: KG | D13: GLAMIR | E13: ABSOLUTOS. | F13: 0.5 | G13: 38230
... A846: 1894 | B846: INS ZOOMZYME GLU10 50G | C846: G | D846: VIA FARMA | E846: COSMETICOS | F846: 0 | G846: 275
A847: 1111111 | B847: KIT ESSENCIALMENTE YOGA - AILLA PACHECO | F847: 0 | G847: 0
A848: 2222222 | B848: KIT MAHA LILAH 2ª EDICAO | F848: 0 | G848: 23.91
A849: 3333333 | B849: KIT S.U.A.VI | F849: 0 | G849: 31.43
A850: 4444444 | B850: KIT VIBRACAO - ESSENCIA DA CRIACAO/MUSICA | F850: 0 | G850: 12.9
A851: 105 | B851: LECITINA DE GIRASSOL 1KG | C851: UN | D851: ADICEL | E851: INSUMOS | F851: 0 | G851: 189.9
A852: 23 | B852: LECITINA DE SOJA LIQUIDA 1KG | C852: UN | D852: ADICEL | E852: INSUMOS | F852: 0 | G852: 14.86
A853: 1080 | B853: LEITE DE COCO EM PO VEGANO 5KG | C853: UN | D853: ADEL COCO BRASIL | E853: PRODUÇÃO | F853: 0 | G853: 212.77
A854: 1081 | B854: LEITE DE COCO EM PO VEGANO LF 5KG | C854: UN | D854: ADEL COCO BRASIL | E854: PRODUÇÃO | F854: 0 | G854: 180.8
A855: 24 | B855: LEITE EM PO PIRACANJUBA | C855: KG | D855: OESA COMERCIO | E855: INSUMOS | F855: 0 | G855: 49
A856: 34 | B856: LICOR DE CACAU | C856: KG | D856: OUTROS | E856: INSUMOS | F856: 0 | G856: 27.6
A857: 793 | B857: LIFE SDHA S10-P2000 (OMEGA 3) | C857: KG | D857: UNIVAR | E857: INSUMOS | F857: 0 | G857: 353.32
A858: 27 | B858: LIMÃO TAHITI GRANULADO 0,4 A 2,0MM 20KG | C858: SC | D858: MACCA DESIDRATADOS | E858: INSUMOS | F858: 0 | G858: 662.6
A859: 5555555 | B859: LIVRO A ALQUIMIA DA MENOPAUSA | F859: 208 | G859: 10.45
A860: 6666666 | B860: LIVRO A BIBLIA DOS OLEOS ESSENCIAIS | F860: 0 | G860: 32.54
A861: 7777777 | B861: LIVRO A BIBLIA PARA TRATAMENTO DE DORES COM | F861: 500 | G861: 24.2
A862: 8888888 | B862: LIVRO A CURA PELO IODO | F862: 0 | G862: 11.15
A863: 9999999 | B863: LIVRO A QUIMICA DOS OLEOS AROMATERAPEUTICOS | F863: 0 | G863: 22
A864: 11111110 | B864: LIVRO A TERAPIA DO MAGNESIO TRANSDERMICO | F864: 108 | G864: 31.04
A865: 12222221 | B865: LIVRO A TIREOIDITE HASHIMOTO | F865: 0 | G865: 13.85
A866: 13333332 | B866: LIVRO A VITAMINA D3 | F866: 0 | G866: 9.75
A867: 14444443 | B867: LIVRO A VITAMINA K2 E O PARADOXO DO CALCIO | F867: 0 | G867: 8.85
A868: 15555554 | B868: LIVRO ALIENIGENAS DO PASSADO SERIE DO HISTORY | F868: 0 | G868: 15.15
A869: 16666665 | B869: LIVRO ALQUIMIA DOS AROMAS PARA A JUVENTUDE | F869: 0 | G869: 8.96
A870: 17777776 | B870: LIVRO ALZHEIMER E O OLFATO | F870: 0 | G870: 23.64
... A928: 82222214 | B928: LIVRO TUDO SOBRE VIRUS | F928: 0 | G928: 10.95
A929: 3461 | B929: MALTITOL CRISTAL ADOÇANTE NATURAL | C929: KG | D929: OUTROS | E929: INSUMOS | F929: 0 | G929: 37.9
...

Sheet Check_Retirada
A1: Código Laszlo | B1: Nome do Produto | C1: Ranking | D1: Preço Custo | E1: Estoque | F1: Status
A2: 776 | B2: ARGILA BRANCA 230G | C2: Retirar de linha | D2: 0 | E2: 0 | F2: ⛔ RETIRADA DE LINHA
A3: 775 | B3: ARGILA PRETA 350G | C3: Retirar de linha | D3: 0 | E3: 0 | F3: ⛔ RETIRADA DE LINHA
A4: 777 | B4: ARGILA VERDE 350G | C4: Retirar de linha | D4: 0 | E4: 0 | F4: ⛔ RETIRADA DE LINHA
A5: 774 | B5: ARGILA VERMELHA 350G | C5: Retirar de linha | D5: 0 | E5: 0 | F5: ⛔ RETIRADA DE LINHA
A6: 1107 | B6: CO ALOEGEL ESFOLIANTE 200G | C6: Retirar de linha | D6: 20.549206 | E6: 0 | F6: ⛔ RETIRADA DE LINHA
A7: 746 | B7: CO GEL NEUTRO 1KG | C7: Retirar de linha | D7: 25.5948 | E7: 75 | F7: ⛔ RETIRADA DE LINHA
A8: 960 | B8: CO GEL NEUTRO 200G | C8: Retirar de linha | D8: 13.21162 | E8: 4 | F8: ⛔ RETIRADA DE LINHA
A9: 1108 | B9: CO MY CREAM PELES NORMAIS E OLEOSAS 1KG | C9: Retirar de linha | D9: 66.7499 | E9: 0 | F9: ⛔ RETIRADA DE LINHA
A10: 1142 | B10: OG MARACUJA 500ML | C10: Retirar de linha | D10: 21.067935 | E10: 0 | F10: ⛔ RETIRADA DE LINHA
A11: 1062 | B11: CHOCOLATE AO LEITE COM OMEGA 3 40 80G | C11: 186 | D11: 3.6 | E11: 12 | F11: ⛔ RETIRADA DE LINHA
A12: 2050 | B12: CHOCOLATE AO LEITE COM ÔMEGA 3 5G | C12: 516 | D12: 0.2389826 | E12: 0 | F12: ⛔ RETIRADA DE LINHA
A13: 1063 | B13: CHOCOLATE BRANCO BETULA DEFUMADA E BARU 40 | C13: 422 | D13: 7.21 | E13: 0 | F13: ⛔ RETIRADA DE LINHA
A14: 2052 | B14: CHOCOLATE BRANCO DE PACOCA 5G | C14: 517 | D14: 0.84187725 | E14: 0 | F14: ⛔ RETIRADA DE LINHA
A15: 2049 | B15: CHOCOLATE BRANCO DE ROSAS E HIBISCO 5G | C15: 518 | D15: 0.890862 | E15: 0 | F15: ⛔ RETIRADA DE LINHA
A16: 829 | B16: CHOCOLATE BRANCO MOUSSE DE LIMAO-SICILIANO 42 | C16: 149 | D16: 7.55 | E16: 0 | F16: ⛔ RETIRADA DE LINHA
A17: 1075 | B17: CHOCOLATE BRANCO ROSAS COM FLORES HIBISCO 44 | C17: 519 | D17: 7.12 | E17: 0 | F17: ⛔ RETIRADA DE LINHA
A18: 1134 | B18: CHOCOLATE BRANCO VEGANO JASMIM COM LEITE 42 | C18: 520 | D18: 6.82 | E18: 0 | F18: ⛔ RETIRADA DE LINHA
A19: 2055 | B19: CHOCOLATE CANELA COM CAFE 60 80G | C19: 217 | D19: 2.54 | E19: 0 | F19: ⛔ RETIRADA DE LINHA
A20: 826 | B20: CHOCOLATE GOLDEN CHAI 42 80G | C20: 201 | D20: 6.24 | E20: 0 | F20: ⛔ RETIRADA DE LINHA
A21: 2047 | B21: CHOCOLATE GOLDEN CHAI 5G | C21: 521 | D21: 1.0444956 | E21: 0 | F21: ⛔ RETIRADA DE LINHA
A22: 2048 | B22: CHOCOLATE LAVANDA FINA BULGARIA E AMENDOAS 5G | C22: 522 | D22: 0.89917811 | E22: 0 | F22: ⛔ RETIRADA DE LINHA
... A49: 1432 | B49: EXTRATO QE SALVIA 10ML | C49: 567 | D49: 2.61139 | E49: 0 | F49: ⛔ RETIRADA DE LINHA

Sheet Parâmetros v3
A1: DOMME MOTOR v3 — PARÂMETROS GLOBAIS
A3: MARGENS E TAXAS
A4: MIL — Margem Industrial Laszlo | B4: 0.4
A5: MD — Margem Comercial DOMME | B5: 0.2
A6: Selo Laszlo | B6: 0.03
A7: Tier 1 — Markup (≤500 un/lote) | B7: 0.2
A8: Tier 2 — Markup (501-2000 un/lote) | B8: 0.1
A9: Tier 3 — Markup (>2000 un/lote) | B9: 0
A10: Desconto kit | B10: 0.05
A11: Embalagem kit (R$) | B11: 5.5
A13: FEES DOMME
A14: Fee Estruturação (fixo) | B14: 1500
A16: ESCALA v3
A17: Limite lote fator 2x | B17: 100
A18: Fator escala pequeno | B18: 2
A20: TRAVA LASZLO
A21: MC mínima atacado | B21: 0.2
A23: VIABILIDADE
A24: IV máximo (PFC/Varejo) | B24: 0.55
A26: EXPORTAÇÃO
A27: Markup internacional OEs | B27: 8
A29: ROI CONSERVADOR
A30: Desc. impostos+frete | B30: 0.15

Sheet Regras v3
A1: DOMME MOTOR v3 — REGRAS DE NEGÓCIO
A3: 1. INTELIGÊNCIA DE CUSTOS
A4: CVU puxado da aba "Catálogo Laszlo" (Preço Custo Real da fábrica)
A5: Lotes ≤100un: insumos de envase (frasco/tampa/gotejador) multiplicados por 2x
A6: Trava: Laszlo mantém mínimo 20% MC no atacado — alerta automático se violado
A7: SKUs em "Check_Retirada" bloqueiam o cálculo com alerta visual ⛔
A9: 2. ESTRUTURA v3
A10: Volume = por Lote/Pedido (não mais anual)
A11: Full-Service obrigatório: Kit Envase + Fee DOMME R$1.500 fixo
A12: Fee rateado por unidade: R$1.500 ÷ qtd do lote
A13: Tiers por lote: T1≤500 (+20%) | T2≤2000 (+10%) | T3>2000 (0%)
A15: 3. MÉTRICAS DE SUCESSO
... A30: Foco regulatório: Aromas Naturais / Alimentos para rapidez de mercado
